Traceback (most recent call last):
  File "/Users/srdanverbic/anaconda3/lib/python3.6/site-packages/jupyter_cache/executors/utils.py", line 56, in single_nb_execution
    record_timing=False,
  File "/Users/srdanverbic/anaconda3/lib/python3.6/site-packages/nbclient/client.py", line 1093, in execute
    return NotebookClient(nb=nb, resources=resources, km=km, **kwargs).execute()
  File "/Users/srdanverbic/anaconda3/lib/python3.6/site-packages/nbclient/util.py", line 84, in wrapped
    return just_run(coro(*args, **kwargs))
  File "/Users/srdanverbic/anaconda3/lib/python3.6/site-packages/nbclient/util.py", line 62, in just_run
    return loop.run_until_complete(coro)
  File "/Users/srdanverbic/anaconda3/lib/python3.6/asyncio/base_events.py", line 484, in run_until_complete
    return future.result()
  File "/Users/srdanverbic/anaconda3/lib/python3.6/site-packages/nbclient/client.py", line 560, in async_execute
    cell, index, execution_count=self.code_cells_executed + 1
  File "/Users/srdanverbic/anaconda3/lib/python3.6/site-packages/nbclient/client.py", line 854, in async_execute_cell
    self._check_raise_for_error(cell, exec_reply)
  File "/Users/srdanverbic/anaconda3/lib/python3.6/site-packages/nbclient/client.py", line 756, in _check_raise_for_error
    raise CellExecutionError.from_cell_and_msg(cell, exec_reply_content)
nbclient.exceptions.CellExecutionError: An error occurred while executing the following cell:
------------------
print(df.isna().sum())
------------------

[0;31m---------------------------------------------------------------------------[0m
[0;31mAttributeError[0m                            Traceback (most recent call last)
[0;32m<ipython-input-5-c30d0d9ddb1c>[0m in [0;36m<module>[0;34m[0m
[0;32m----> 1[0;31m [0mprint[0m[0;34m([0m[0mdf[0m[0;34m.[0m[0misna[0m[0;34m([0m[0;34m)[0m[0;34m.[0m[0msum[0m[0;34m([0m[0;34m)[0m[0;34m)[0m[0;34m[0m[0;34m[0m[0m
[0m
[0;32m~/anaconda3/lib/python3.6/site-packages/pandas/core/generic.py[0m in [0;36m__getattr__[0;34m(self, name)[0m
[1;32m   3079[0m             [0;32mif[0m [0mname[0m [0;32min[0m [0mself[0m[0;34m.[0m[0m_info_axis[0m[0;34m:[0m[0;34m[0m[0;34m[0m[0m
[1;32m   3080[0m                 [0;32mreturn[0m [0mself[0m[0;34m[[0m[0mname[0m[0;34m][0m[0;34m[0m[0;34m[0m[0m
[0;32m-> 3081[0;31m             [0;32mreturn[0m [0mobject[0m[0;34m.[0m[0m__getattribute__[0m[0;34m([0m[0mself[0m[0;34m,[0m [0mname[0m[0;34m)[0m[0;34m[0m[0;34m[0m[0m
[0m[1;32m   3082[0m [0;34m[0m[0m
[1;32m   3083[0m     [0;32mdef[0m [0m__setattr__[0m[0;34m([0m[0mself[0m[0;34m,[0m [0mname[0m[0;34m,[0m [0mvalue[0m[0;34m)[0m[0;34m:[0m[0;34m[0m[0;34m[0m[0m

[0;31mAttributeError[0m: 'DataFrame' object has no attribute 'isna'
AttributeError: 'DataFrame' object has no attribute 'isna'

